Workbook

Sheet empresas_filtradas
A1: cnpj | B1: nome_fantasia | C1: situacao_cadastral | D1: pais | E1: cnae_principal | F1: numero | G1: complemento | H1: cep | I1: uf | J1: municipio | K1: email | L1: se | M1: veredito | N1: output | O1: local
A2: 35820448004557 | C2: 2 | E2: 2014200 | F2: S/N | H2: 35970000 | I2: MG | J2: 4107 | K2: WHITEMARTINS | L2: {=IF(SUMPRODUCT(COUNTIF(empresas_filtradas[[#This Row],[cnpj]:[email]],"*"&#REF!&"*"))>0,"sim","não")} -> não | M2: Potencial Planta | N2: =_xlfn.XLOOKUP(empresas_filtradas[[#This Row],[cnpj]], empresas_identificadas_compleme!A:A, empresas_identificadas_compleme!B:B) -> produz_h2 | O2: =_xlfn.XLOOKUP(empresas_filtradas[[#This Row],[cnpj]], empresas_identificadas_compleme!A:A, empresas_identificadas_compleme!C:C) -> CTF_APP e 80km
A3: 60619202001896 | C3: 3 | E3: 2014200 | F3: 65 | H3: 57080010 | I3: AL | J3: 2785 | K3: rita.rocha@br.aga.com | L3: {=IF(SUMPRODUCT(COUNTIF(empresas_filtradas[[#This Row],[cnpj]:[email]],"*"&#REF!&"*"))>0,"sim","não")} -> não | M3: Sem Relação | N3: =_xlfn.XLOOKUP(empresas_filtradas[[#This Row],[cnpj]], empresas_identificadas_compleme!A:A, empresas_identificadas_compleme!B:B) -> talvez | O3: =_xlfn.XLOOKUP(empresas_filtradas[[#This Row],[cnpj]], empresas_identificadas_compleme!A:A, empresas_identificadas_compleme!C:C) -> 80km
A4: 60619202000490 | B4: MESSER GASES | C4: 2 | E4: 2014200 | F4: 1825 | H4: 78098370 | I4: MT | J4: 9067 | K4: TAX.COMPLIANCE@MESSER-BR.COM | L4: {=IF(SUMPRODUCT(COUNTIF(empresas_filtradas[[#This Row],[cnpj]:[email]],"*"&#REF!&"*"))>0,"sim","não")} -> não | M4: Não Planta | N4: =_xlfn.XLOOKUP(empresas_filtradas[[#This Row],[cnpj]], empresas_identificadas_compleme!A:A, empresas_identificadas_compleme!B:B) -> talvez | O4: =_xlfn.XLOOKUP(empresas_filtradas[[#This Row],[cnpj]], empresas_identificadas_compleme!A:A, empresas_identificadas_compleme!C:C) -> CTF_APP
A5: 331788004530 | C5: 2 | E5: 2014200 | F5: S/ N | G5: PARTE | H5: 23570000 | I5: RJ | J5: 6001 | K5: BRALB-PARALEGAL@AIRLIQUIDE.COM | L5: {=IF(SUMPRODUCT(COUNTIF(empresas_filtradas[[#This Row],[cnpj]:[email]],"*"&#REF!&"*"))>0,"sim","não")} -> não | M5: Potencial Planta | N5: =_xlfn.XLOOKUP(empresas_filtradas[[#This Row],[cnpj]], empresas_identificadas_compleme!A:A, empresas_identificadas_compleme!B:B) -> talvez | O5: =_xlfn.XLOOKUP(empresas_filtradas[[#This Row],[cnpj]], empresas_identificadas_compleme!A:A, empresas_identificadas_compleme!C:C) -> 80km
A6: 8892204000196 | C6: 2 | E6: 2014200 | F6: 00003 | H6: 20921392 | I6: RJ | J6: 6001 | K6: NFE.ENTRADA@RECIGASES.COM | L6: {=IF(SUMPRODUCT(COUNTIF(empresas_filtradas[[#This Row],[cnpj]:[email]],"*"&#REF!&"*"))>0,"sim","não")} -> não | M6: Sem Relação | N6: =_xlfn.XLOOKUP(empresas_filtradas[[#This Row],[cnpj]], empresas_identificadas_compleme!A:A, empresas_identificadas_compleme!B:B) -> talvez | O6: =_xlfn.XLOOKUP(empresas_filtradas[[#This Row],[cnpj]], empresas_identificadas_compleme!A:A, empresas_identificadas_compleme!C:C) -> 80km
A7: 35820448019317 | C7: 2 | E7: 2014200 | F7: 660 | H7: 13505645 | I7: SP | J7: 6979 | K7: ATENDIMENTO@SAC.WHITEMARTINS.COM.BR | L7: {=IF(SUMPRODUCT(COUNTIF(empresas_filtradas[[#This Row],[cnpj]:[email]],"*"&#REF!&"*"))>0,"sim","não")} -> não | M7: Potencial Planta | N7: =_xlfn.XLOOKUP(empresas_filtradas[[#This Row],[cnpj]], empresas_identificadas_compleme!A:A, empresas_identificadas_compleme!B:B) -> talvez | O7: =_xlfn.XLOOKUP(empresas_filtradas[[#This Row],[cnpj]], empresas_identificadas_compleme!A:A, empresas_identificadas_compleme!C:C) -> CTF_APP e 80km
A8: 10911087000102 | C8: 2 | E8: 2014200 | F8: 406 | H8: 13183660 | I8: SP | J8: 2951 | K8: HORTOOXI@GMAIL.COM | L8: {=IF(SUMPRODUCT(COUNTIF(empresas_filtradas[[#This Row],[cnpj]:[email]],"*"&#REF!&"*"))>0,"sim","não")} -> não | M8: Sem Relação | N8: =_xlfn.XLOOKUP(empresas_filtradas[[#This Row],[cnpj]], empresas_identificadas_compleme!A:A, empresas_identificadas_compleme!B:B) -> incerto | O8: =_xlfn.XLOOKUP(empresas_filtradas[[#This Row],[cnpj]], empresas_identificadas_compleme!A:A, empresas_identificadas_compleme!C:C) -> 80km
A9: 43843358003023 | C9: 2 | E9: 2014200 | F9: S/N | G9: KM 28,5 - PARTE | H9: 18278725 | I9: SP | J9: 7181 | K9: IMPNFE@AIRPRODUCTS.COM | L9: {=IF(SUMPRODUCT(COUNTIF(empresas_filtradas[[#This Row],[cnpj]:[email]],"*"&#REF!&"*"))>0,"sim","não")} -> não | M9: Não Planta | N9: =_xlfn.XLOOKUP(empresas_filtradas[[#This Row],[cnpj]], empresas_identificadas_compleme!A:A, empresas_identificadas_compleme!B:B) -> talvez | O9: =_xlfn.XLOOKUP(empresas_filtradas[[#This Row],[cnpj]], empresas_identificadas_compleme!A:A, empresas_identificadas_compleme!C:C) -> CTF_APP
A10: 331788005773 | B10: AIR LIQUIDE BRASIL LTDA | C10: 2 | E10: 2014200 | F10: 01 | H10: 71225526 | I10: DF | J10: 9701 | K10: BRALB-PARALEGAL@AIRLIQUIDE.COM | L10: {=IF(SUMPRODUCT(COUNTIF(empresas_filtradas[[#This Row],[cnpj]:[email]],"*"&#REF!&"*"))>0,"sim","não")} -> não | M10: Não Planta | N10: =_xlfn.XLOOKUP(empresas_filtradas[[#This Row],[cnpj]], empresas_identificadas_compleme!A:A, empresas_identificadas_compleme!B:B) -> talvez | O10: =_xlfn.XLOOKUP(empresas_filtradas[[#This Row],[cnpj]], empresas_identificadas_compleme!A:A, empresas_identificadas_compleme!C:C) -> CTF_APP
A11: 331788006230 | B11: AIR LIQUIDE BRASIL LTDA | C11: 2 | E11: 2014200 | F11: 2-71 | G11: QUADRA PI2 | H11: 17034290 | I11: SP | J11: 6219 | K11: BRALB-PARALEGAL@AIRLIQUIDE.COM | L11: {=IF(SUMPRODUCT(COUNTIF(empresas_filtradas[[#This Row],[cnpj]:[email]],"*"&#REF!&"*"))>0,"sim","não")} -> não | M11: Não Planta | N11: =_xlfn.XLOOKUP(empresas_filtradas[[#This Row],[cnpj]], empresas_identificadas_compleme!A:A, empresas_identificadas_compleme!B:B) -> talvez | O11: =_xlfn.XLOOKUP(empresas_filtradas[[#This Row],[cnpj]], empresas_identificadas_compleme!A:A, empresas_identificadas_compleme!C:C) -> CTF_APP
A12: 12201621000112 | B12: OXIGENIO NOVA GERACAO | C12: 2 | E12: 2014200 | F12: 1959 | H12: 81650060 | I12: PR | J12: 7535 | K12: AXIGAS@AXIGAS.COM.BR | L12: {=IF(SUMPRODUCT(COUNTIF(empresas_filtradas[[#This Row],[cnpj]:[email]],"*"&#REF!&"*"))>0,"sim","não")} -> não | M12: Relação | N12: =_xlfn.XLOOKUP(empresas_filtradas[[#This Row],[cnpj]], empresas_identificadas_compleme!A:A, empresas_identificadas_compleme!B:B) -> talvez | O12: =_xlfn.XLOOKUP(empresas_filtradas[[#This Row],[cnpj]], empresas_identificadas_compleme!A:A, empresas_identificadas_compleme!C:C) -> 80km
A13: 22290296000165 | B13: OXGAS | C13: 2 | E13: 2014200 | F13: 1094 | H13: 29157025 | I13: ES | J13: 5625 | K13: CONTABIL@OXGAS.COM.BR | L13: {=IF(SUMPRODUCT(COUNTIF(empresas_filtradas[[#This Row],[cnpj]:[email]],"*"&#REF!&"*"))>0,"sim","não")} -> não | M13: Sem Relação | N13: =_xlfn.XLOOKUP(empresas_filtradas[[#This Row],[cnpj]], empresas_identificadas_compleme!A:A, empresas_identificadas_compleme!B:B) -> talvez | O13: =_xlfn.XLOOKUP(empresas_filtradas[[#This Row],[cnpj]], empresas_identificadas_compleme!A:A, empresas_identificadas_compleme!C:C) -> 80km
A14: 24539446000157 | B14: PCI | C14: 2 | D14: 249 | E14: 2014200 | F14: S/N | G14: 925034820 | I14: EX | J14: 9707 | K14: SERES.BAUM@WGI.ONE | L14: {=IF(SUMPRODUCT(COUNTIF(empresas_filtradas[[#This Row],[cnpj]:[email]],"*"&#REF!&"*"))>0,"sim","não")} -> não | M14: Sem Relação | N14: =_xlfn.XLOOKUP(empresas_filtradas[[#This Row],[cnpj]], empresas_identificadas_compleme!A:A, empresas_identificadas_compleme!B:B) -> talvez | O14: =_xlfn.XLOOKUP(empresas_filtradas[[#This Row],[cnpj]], empresas_identificadas_compleme!A:A, empresas_identificadas_compleme!C:C) -> 0
A15: 11501268000123 | C15: 2 | E15: 2014200 | F15: 08 | H15: 65911769 | I15: MA | J15: 803 | K15: TROPICALIMPORTADORA@CONTADORGESTOR.COM.BR | L15: {=IF(SUMPRODUCT(COUNTIF(empresas_filtradas[[#This Row],[cnpj]:[email]],"*"&#REF!&"*"))>0,"sim","não")} -> não | M15: Sem Relação | N15: =_xlfn.XLOOKUP(empresas_filtradas[[#This Row],[cnpj]], empresas_identificadas_compleme!A:A, empresas_identificadas_compleme!B:B) -> incerto | O15: =_xlfn.XLOOKUP(empresas_filtradas[[#This Row],[cnpj]], empresas_identificadas_compleme!A:A, empresas_identificadas_compleme!C:C) -> 0
A16: 60619202002272 | B16: MESSER GASES | C16: 2 | E16: 2014200 | F16: 824 | G16: QUADRA15 E 20 | H16: 42816140 | I16: BA | J16: 3413 | K16: TAX.COMPLIANCE@MESSER-BR.COM | L16: {=IF(SUMPRODUCT(COUNTIF(empresas_filtradas[[#This Row],[cnpj]:[email]],"*"&#REF!&"*"))>0,"sim","não")} -> não | M16: Potencial Planta | N16: =_xlfn.XLOOKUP(empresas_filtradas[[#This Row],[cnpj]], empresas_identificadas_compleme!A:A, empresas_identificadas_compleme!B:B) -> talvez | O16: =_xlfn.XLOOKUP(empresas_filtradas[[#This Row],[cnpj]], empresas_identificadas_compleme!A:A, empresas_identificadas_compleme!C:C) -> CTF_APP e 80km
A17: 24380578005903 | C17: 2 | E17: 2014200 | F17: S/N | G17: KM 20 | H17: 79602970 | I17: MS | J17: 9165 | K17: ATENDIMENTO@SAC.WHITEMARTINS.COM.BR | L17: {=IF(SUMPRODUCT(COUNTIF(empresas_filtradas[[#This Row],[cnpj]:[email]],"*"&#REF!&"*"))>0,"sim","não")} -> não | M17: Não Planta | N17: =_xlfn.XLOOKUP(empresas_filtradas[[#This Row],[cnpj]], empresas_identificadas_compleme!A:A, empresas_identificadas_compleme!B:B) -> talvez | O17: =_xlfn.XLOOKUP(empresas_filtradas[[#This Row],[cnpj]], empresas_identificadas_compleme!A:A, empresas_identificadas_compleme!C:C) -> CTF_APP
A18: 26288918000171 | C18: 2 | E18: 2014200 | F18: 330 | G18: GALPAO04 | H18: 89245000 | I18: SC | J18: 8025 | K18: SOCIETARIO1@ATOS.CNT.BR | L18: {=IF(SUMPRODUCT(COUNTIF(empresas_filtradas[[#This Row],[cnpj]:[email]],"*"&#REF!&"*"))>0,"sim","não")} -> não | M18: Sem Relação | N18: =_xlfn.XLOOKUP(empresas_filtradas[[#This Row],[cnpj]], empresas_identificadas_compleme!A:A, empresas_identificadas_compleme!B:B) -> incerto | O18: =_xlfn.XLOOKUP(empresas_filtradas[[#This Row],[cnpj]], empresas_identificadas_compleme!A:A, empresas_identificadas_compleme!C:C) -> 0
A19: 35820448021303 | C19: 2 | E19: 2014200 | F19: 255 | H19: 13288172 | I19: SP | J19: 7237 | K19: ATENDIMENTO@SAC.WHITEMARTINS.COM.BR | L19: {=IF(SUMPRODUCT(COUNTIF(empresas_filtradas[[#This Row],[cnpj]:[email]],"*"&#REF!&"*"))>0,"sim","não")} -> não | M19: Potencial Planta | N19: =_xlfn.XLOOKUP(empresas_filtradas[[#This Row],[cnpj]], empresas_identificadas_compleme!A:A, empresas_identificadas_compleme!B:B) -> talvez | O19: =_xlfn.XLOOKUP(empresas_filtradas[[#This Row],[cnpj]], empresas_identificadas_compleme!A:A, empresas_identificadas_compleme!C:C) -> CTF_APP e 80km
A20: 35820448022024 | C20: 2 | E20: 2014200 | F20: S/N | G20: KM 547 ANEXO ENTRADA PELA ROD. LMG 748 KM 29 SENTIDO ARAGUARI | H20: 38490000 | I20: MG | J20: 4613 | K20: ATENDIMENTO@SAC.WHITEMARTINS.COM.BR | L20: {=IF(SUMPRODUCT(COUNTIF(empresas_filtradas[[#This Row],[cnpj]:[email]],"*"&#REF!&"*"))>0,"sim","não")} -> não | M20: Potencial Planta | N20: =_xlfn.XLOOKUP(empresas_filtradas[[#This Row],[cnpj]], empresas_identificadas_compleme!A:A, empresas_identificadas_compleme!B:B) -> talvez | O20: =_xlfn.XLOOKUP(empresas_filtradas[[#This Row],[cnpj]], empresas_identificadas_compleme!A:A, empresas_identificadas_compleme!C:C) -> CTF_APP e 80km
A21: 42315528000108 | B21: TELEGAS INDUSTRIA E COMERCIO | C21: 2 | E21: 2014200 | F21: S/N | G21: QUADRAB LOTE 20 E 40 | H21: 59147325 | I21: RN | J21: 1779 | K21: FDEADOSSANTOS@GMAIL.COM | L21: {=IF(SUMPRODUCT(COUNTIF(empresas_filtradas[[#This Row],[cnpj]:[email]],"*"&#REF!&"*"))>0,"sim","não")} -> não | M21: Sem Relação | N21: =_xlfn.XLOOKUP(empresas_filtradas[[#This Row],[cnpj]], empresas_identificadas_compleme!A:A, empresas_identificadas_compleme!B:B) -> talvez | O21: =_xlfn.XLOOKUP(empresas_filtradas[[#This Row],[cnpj]], empresas_identificadas_compleme!A:A, empresas_identificadas_compleme!C:C) -> 0
A22: 45829243000175 | B22: TRUCKS EVAN U.S.A. HIDROGENIO | C22: 2 | E22: 2014200 | F22: 480 | G22: LOJA | H22: 36052590 | I22: MG | J22: 4733 | K22: CONTABILIDADE@KSCONTABIL.COM.BR | L22: {=IF(SUMPRODUCT(COUNTIF(empresas_filtradas[[#This Row],[cnpj]:[email]],"*"&#REF!&"*"))>0,"sim","não")} -> não | M22: Sem Relação | N22: =_xlfn.XLOOKUP(empresas_filtradas[[#This Row],[cnpj]], empresas_identificadas_compleme!A:A, empresas_identificadas_compleme!B:B) -> talvez | O22: =_xlfn.XLOOKUP(empresas_filtradas[[#This Row],[cnpj]], empresas_identificadas_compleme!A:A, empresas_identificadas_compleme!C:C) -> 0
A23: 63634596000444 | C23: 2 | E23: 2014200 | F23: S/N | G23: KM 1565 | H23: 68632000 | I23: PA | J23: 623 | K23: TRIBUTARIOGS@GRUPOSIMOES.COM.BR | L23: {=IF(SUMPRODUCT(COUNTIF(empresas_filtradas[[#This Row],[cnpj]:[email]],"*"&#REF!&"*"))>0,"sim","não")} -> não | M23: Sem Relação | N23: =_xlfn.XLOOKUP(empresas_filtradas[[#This Row],[cnpj]], empresas_identificadas_compleme!A:A, empresas_identificadas_compleme!B:B) -> incerto | O23: =_xlfn.XLOOKUP(empresas_filtradas[[#This Row],[cnpj]], empresas_identificadas_compleme!A:A, empresas_identificadas_compleme!C:C) -> CTF_APP
A24: 52238156000109 | C24: 2 | E24: 2014200 | F24: 1781 | H24: 27197000 | I24: RJ | J24: 778 | K24: ASPCONTABILIDADEVR@HOTMAIL.COM | L24: {=IF(SUMPRODUCT(COUNTIF(empresas_filtradas[[#This Row],[cnpj]:[email]],"*"&#REF!&"*"))>0,"sim","não")} -> não | M24: Sem Relação | N24: =_xlfn.XLOOKUP(empresas_filtradas[[#This Row],[cnpj]], empresas_identificadas_compleme!A:A, empresas_identificadas_compleme!B:B) -> incerto | O24: =_xlfn.XLOOKUP(empresas_filtradas[[#This Row],[cnpj]], empresas_identificadas_compleme!A:A, empresas_identificadas_compleme!C:C) -> 80km
A25: 52315566000106 | C25: 2 | E25: 2014200 | F25: 1777 | G25: SALA 1107 | H25: 30170008 | I25: MG | J25: 4123 | K25: CGF@SOLATIO.COM.BR | L25: {=IF(SUMPRODUCT(COUNTIF(empresas_filtradas[[#This Row],[cnpj]:[email]],"*"&#REF!&"*"))>0,"sim","não")} -> não | M25: Conceito de Planta | N25: =_xlfn.XLOOKUP(empresas_filtradas[[#This Row],[cnpj]], empresas_identificadas_compleme!A:A, empresas_identificadas_compleme!B:B) -> talvez | O25: =_xlfn.XLOOKUP(empresas_filtradas[[#This Row],[cnpj]], empresas_identificadas_compleme!A:A, empresas_identificadas_compleme!C:C) -> 80km
A26: 54443328000101 | B26: GEP-PIAUI | C26: 2 | D26: 105 | E26: 2014200 | F26: S/N | G26: CXPST 60 | H26: 64200970 | I26: PI | J26: 1153 | K26: INFO@GEP-GLOBAL.COM | L26: {=IF(SUMPRODUCT(COUNTIF(empresas_filtradas[[#This Row],[cnpj]:[email]],"*"&#REF!&"*"))>0,"sim","não")} -> não | M26: Conceito de Planta | N26: =_xlfn.XLOOKUP(empresas_filtradas[[#This Row],[cnpj]], empresas_identificadas_compleme!A:A, empresas_identificadas_compleme!B:B) -> talvez | O26: =_xlfn.XLOOKUP(empresas_filtradas[[#This Row],[cnpj]], empresas_identificadas_compleme!A:A, empresas_identificadas_compleme!C:C) -> 0
A27: 55482177000163 | B27: OXINE | C27: 2 | E27: 2014200 | F27: 300 | G27: GALPAO | H27: 55660000 | I27: PE | J27: 2337 | K27: SILTON@SILTON.COM.BR | L27: {=IF(SUMPRODUCT(COUNTIF(empresas_filtradas[[#This Row],[cnpj]:[email]],"*"&#REF!&"*"))>0,"sim","não")} -> não | M27: Sem Relação | N27: =_xlfn.XLOOKUP(empresas_filtradas[[#This Row],[cnpj]], empresas_identificadas_compleme!A:A, empresas_identificadas_compleme!B:B) -> #N/A | O27: =_xlfn.XLOOKUP(empresas_filtradas[[#This Row],[cnpj]], empresas_identificadas_compleme!A:A, empresas_identificadas_compleme!C:C) -> #N/A
A28: 57155559000108 | B28: SOS GASES INDUSTRIAIS | C28: 2 | D28: 105 | E28: 2014200 | F28: 1300 | H28: 58069263 | I28: PB | J28: 2051 | K28: SOSGASESINDUSTRIA@GMAIL.COM | L28: {=IF(SUMPRODUCT(COUNTIF(empresas_filtradas[[#This Row],[cnpj]:[email]],"*"&#REF!&"*"))>0,"sim","não")} -> não | M28: Sem Relação | N28: =_xlfn.XLOOKUP(empresas_filtradas[[#This Row],[cnpj]], empresas_identificadas_compleme!A:A, empresas_identificadas_compleme!B:B) -> incerto | O28: =_xlfn.XLOOKUP(empresas_filtradas[[#This Row],[cnpj]], empresas_identificadas_compleme!A:A, empresas_identificadas_compleme!C:C) -> 0
A29: 45517186000199 | B29: OXIGENIO CAROL | C29: 2 | E29: 2014200 | F29: 420 | G29: GALPAO02 | H29: 18105008 | I29: SP | J29: 7145 | K29: LEGALIZACAO@FIDERECONTABIL.COM.BR | L29: {=IF(SUMPRODUCT(COUNTIF(empresas_filtradas[[#This Row],[cnpj]:[email]],"*"&#REF!&"*"))>0,"sim","não")} -> não | M29: Sem Relação | N29: =_xlfn.XLOOKUP(empresas_filtradas[[#This Row],[cnpj]], empresas_identificadas_compleme!A:A, empresas_identificadas_compleme!B:B) -> #N/A | O29: =_xlfn.XLOOKUP(empresas_filtradas[[#This Row],[cnpj]], empresas_identificadas_compleme!A:A, empresas_identificadas_compleme!C:C) -> #N/A
A30: 331788010939 | C30: 2 | E30: 2014200 | F30: S/N | G30: KM 11 5 | H30: 42813760 | I30: BA | J30: 3413 | K30: BRALB-PARALEGAL@AIRLIQUIDE.COM | L30: {=IF(SUMPRODUCT(COUNTIF(empresas_filtradas[[#This Row],[cnpj]:[email]],"*"&#REF!&"*"))>0,"sim","não")} -> não | M30: Não Planta | N30: =_xlfn.XLOOKUP(empresas_filtradas[[#This Row],[cnpj]], empresas_identificadas_compleme!A:A, empresas_identificadas_compleme!B:B) -> talvez | O30: =_xlfn.XLOOKUP(empresas_filtradas[[#This Row],[cnpj]], empresas_identificadas_compleme!A:A, empresas_identificadas_compleme!C:C) -> 80km
A31: 61598154000111 | B31: ECO-GASES | C31: 2 | D31: 105 | E31: 2014200 | F31: 178-B | H31: 58410430 | I31: PB | J31: 1981 | K31: ECOGASESCG@GMAIL.COM | L31: {=IF(SUMPRODUCT(COUNTIF(empresas_filtradas[[#This Row],[cnpj]:[email]],"*"&#REF!&"*"))>0,"sim","não")} -> não | M31: Sem Relação | N31: =_xlfn.XLOOKUP(empresas_filtradas[[#This Row],[cnpj]], empresas_identificadas_compleme!A:A, empresas_identificadas_compleme!B:B) -> #N/A | O31: =_xlfn.XLOOKUP(empresas_filtradas[[#This Row],[cnpj]], empresas_identificadas_compleme!A:A, empresas_identificadas_compleme!C:C) -> #N/A
A32: 55482177000325 | B32: OXINE | C32: 2 | E32: 2014200 | F32: 1170 | G32: C | H32: 60875010 | I32: CE | J32: 1389 | K32: SILTON@SILTON.COM.BR | L32: {=IF(SUMPRODUCT(COUNTIF(empresas_filtradas[[#This Row],[cnpj]:[email]],"*"&#REF!&"*"))>0,"sim","não")} -> não | M32: Relação | N32: =_xlfn.XLOOKUP(empresas_filtradas[[#This Row],[cnpj]], empresas_identificadas_compleme!A:A, empresas_identificadas_compleme!B:B) -> talvez | O32: =_xlfn.XLOOKUP(empresas_filtradas[[#This Row],[cnpj]], empresas_identificadas_compleme!A:A, empresas_identificadas_compleme!C:C) -> 80km
A33: 331788000623 | C33: 2 | E33: 2014200 | F33: 650 | H33: 26110100 | I33: RJ | J33: 2909 | K33: BRALB-PARALEGAL@AIRLIQUIDE.COM | L33: {=IF(SUMPRODUCT(COUNTIF(empresas_filtradas[[#This Row],[cnpj]:[email]],"*"&#REF!&"*"))>0,"sim","não")} -> não | M33: Potencial Planta | N33: =_xlfn.XLOOKUP(empresas_filtradas[[#This Row],[cnpj]], empresas_identificadas_compleme!A:A, empresas_identificadas_compleme!B:B) -> talvez | O33: =_xlfn.XLOOKUP(empresas_filtradas[[#This Row],[cnpj]], empresas_identificadas_compleme!A:A, empresas_identificadas_compleme!C:C) -> CTF_APP e 80km
A34: 2314026000130 | B34: Q FRIO | C34: 2 | E34: 2014200 | F34: 769 | H34: 50751312 | I34: PE | J34: 2531 | K34: FLAVIO@QFRIOGELOSECO.COM.BR | L34: {=IF(SUMPRODUCT(COUNTIF(empresas_filtradas[[#This Row],[cnpj]:[email]],"*"&#REF!&"*"))>0,"sim","não")} -> não | M34: Sem Relação | N34: =_xlfn.XLOOKUP(empresas_filtradas[[#This Row],[cnpj]], empresas_identificadas_compleme!A:A, empresas_identificadas_compleme!B:B) -> #N/A | O34: =_xlfn.XLOOKUP(empresas_filtradas[[#This Row],[cnpj]], empresas_identificadas_compleme!A:A, empresas_identificadas_compleme!C:C) -> #N/A
A35: 5914165000192 | C35: 2 | E35: 2014200 | F35: 897 | H35: 69008445 | I35: AM | J35: 255 | K35: EUDNEY.SOUSA@CARBOXIGASES.COM | L35: {=IF(SUMPRODUCT(COUNTIF(empresas_filtradas[[#This Row],[cnpj]:[email]],"*"&#REF!&"*"))>0,"sim","não")} -> não | M35: Sem Relação | N35: =_xlfn.XLOOKUP(empresas_filtradas[[#This Row],[cnpj]], empresas_identificadas_compleme!A:A, empresas_identificadas_compleme!B:B) -> talvez | O35: =_xlfn.XLOOKUP(empresas_filtradas[[#This Row],[cnpj]], empresas_identificadas_compleme!A:A, empresas_identificadas_compleme!C:C) -> CTF_APP
A36: 35820448006410 | C36: 2 | E36: 2014200 | F36: S/N | G36: LOTE 26 | H36: 95840000 | I36: RS | J36: 8943 | K36: ATENDIMENTO@SAC.WHITEMARTINS.COM.BR | L36: {=IF(SUMPRODUCT(COUNTIF(empresas_filtradas[[#This Row],[cnpj]:[email]],"*"&#REF!&"*"))>0,"sim","não")} -> não | M36: Potencial Planta | N36: =_xlfn.XLOOKUP(empresas_filtradas[[#This Row],[cnpj]], empresas_identificadas_compleme!A:A, empresas_identificadas_compleme!B:B) -> talvez | O36: =_xlfn.XLOOKUP(empresas_filtradas[[#This Row],[cnpj]], empresas_identificadas_compleme!A:A, empresas_identificadas_compleme!C:C) -> CTF_APP e 80km
A37: 35820448010360 | C37: 2 | E37: 2014200 | F37: 500 | H37: 13212240 | I37: SP | J37: 6619 | K37: ATENDIMENTO@SAC.WHITEMARTINS.COM.BR | L37: {=IF(SUMPRODUCT(COUNTIF(empresas_filtradas[[#This Row],[cnpj]:[email]],"*"&#REF!&"*"))>0,"sim","não")} -> não | M37: Potencial Planta | N37: =_xlfn.XLOOKUP(empresas_filtradas[[#This Row],[cnpj]], empresas_identificadas_compleme!A:A, empresas_identificadas_compleme!B:B) -> talvez | O37: =_xlfn.XLOOKUP(empresas_filtradas[[#This Row],[cnpj]], empresas_identificadas_compleme!A:A, empresas_identificadas_compleme!C:C) -> CTF_APP e 80km
A38: 35820448015915 | B38: WHITE MARTINS | C38: 2 | E38: 2014200 | F38: 2220 | H38: 13473625 | I38: SP | J38: 6131 | K38: ATENDIMENTO@SAC.WHITEMARTINS.COM.BR | L38: {=IF(SUMPRODUCT(COUNTIF(empresas_filtradas[[#This Row],[cnpj]:[email]],"*"&#REF!&"*"))>0,"sim","não")} -> não | M38: Potencial Planta | N38: =_xlfn.XLOOKUP(empresas_filtradas[[#This Row],[cnpj]], empresas_identificadas_compleme!A:A, empresas_identificadas_compleme!B:B) -> talvez | O38: =_xlfn.XLOOKUP(empresas_filtradas[[#This Row],[cnpj]], empresas_identificadas_compleme!A:A, empresas_identificadas_compleme!C:C) -> CTF_APP e 80km
A39: 35820448017454 | C39: 2 | E39: 2014200 | F39: S/N | G39: KM 6 ACIARIA 1 AV PLINIO DE QUEIROZ S/N (FOX) | H39: 11573900 | I39: SP | J39: 6371 | K39: ATENDIMENTO@SAC.WHITEMARTINS.COM.BR | L39: {=IF(SUMPRODUCT(COUNTIF(empresas_filtradas[[#This Row],[cnpj]:[email]],"*"&#REF!&"*"))>0,"sim","não")} -> não | M39: Potencial Planta | N39: =_xlfn.XLOOKUP(empresas_filtradas[[#This Row],[cnpj]], empresas_identificadas_compleme!A:A, empresas_identificadas_compleme!B:B) -> talvez | O39: =_xlfn.XLOOKUP(empresas_filtradas[[#This Row],[cnpj]], empresas_identificadas_compleme!A:A, empresas_identificadas_compleme!C:C) -> CTF_APP e 80km
A40: 2605266000355 | B40: MESSER GASES | C40: 2 | E40: 2014200 | F40: 6000 | G40: FABRICA DE OXIGENIO 4 | H40: 29092300 | I40: ES | J40: 5705 | K40: TAX.COMPLIANCE@MESSER-BR.COM | L40: {=IF(SUMPRODUCT(COUNTIF(empresas_filtradas[[#This Row],[cnpj]:[email]],"*"&#REF!&"*"))>0,"sim","não")} -> não | M40: Potencial Planta | N40: =_xlfn.XLOOKUP(empresas_filtradas[[#This Row],[cnpj]], empresas_identificadas_compleme!A:A, empresas_identificadas_compleme!B:B) -> talvez | O40: =_xlfn.XLOOKUP(empresas_filtradas[[#This Row],[cnpj]], empresas_identificadas_compleme!A:A, empresas_identificadas_compleme!C:C) -> CTF_APP e 80km
...

Sheet empresas_identificadas_compleme
A1: cnpj | B1: output | C1: relacao | D1: cep | E1: uf | F1: municipio | G1: polo_mais_proximo | H1: tipo_polo | I1: distancia_min_km | J1: lat | K1: lon | L1: fonte_geo | M1: cidade_geo | N1: uf_geo | O1: observacao_geo | P1: email | Q1: veredito
A2: 60619202001896 | B2: talvez | C2: 80km | D2: 57080010 | E2: AL | F2: 2785 | G2: Marechal Deodoro/AL | H2: quimico_cloroquimico | I2: 20.54 | J2: -9.6072858 | K2: -35.7393 | L2: Nominatim/OpenStreetMap | M2: Maceió | N2: AL | P2: =_xlfn.XLOOKUP(empresas_identificadas_complementadas[[#This Row],[cnpj]],empresas_filtradas[cnpj],empresas_filtradas[email]) -> rita.rocha@br.aga.com | Q2: =_xlfn.XLOOKUP(empresas_identificadas_complementadas[[#This Row],[cnpj]],empresas_filtradas!A:A,empresas_filtradas!M:M) -> Sem Relação
A3: 60619202000490 | B3: talvez | C3: CTF_APP | D3: 78098370 | E3: MT | F3: 9067 | G3: Uberaba/MG | H3: fertilizantes_quimico | I3: 964.58 | J3: -15.668954 | K3: -55.978971 | L3: Nominatim/OpenStreetMap | M3: Cuiabá | N3: MT | P3: =_xlfn.XLOOKUP(empresas_identificadas_complementadas[[#This Row],[cnpj]],empresas_filtradas[cnpj],empresas_filtradas[email]) -> TAX.COMPLIANCE@MESSER-BR.COM | Q3: =_xlfn.XLOOKUP(empresas_identificadas_complementadas[[#This Row],[cnpj]],empresas_filtradas!A:A,empresas_filtradas!M:M) -> Não Planta
A4: 331788004530 | B4: talvez | C4: 80km | D4: 23570000 | E4: RJ | F4: 6001 | G4: Santa Cruz/Ternium/RJ | H4: siderurgia | I4: 6.86 | J4: -22.895226 | K4: -43.739816 | L4: Nominatim/OpenStreetMap | M4: Rio de Janeiro | N4: RJ | P4: =_xlfn.XLOOKUP(empresas_identificadas_complementadas[[#This Row],[cnpj]],empresas_filtradas[cnpj],empresas_filtradas[email]) -> BRALB-PARALEGAL@AIRLIQUIDE.COM | Q4: =_xlfn.XLOOKUP(empresas_identificadas_complementadas[[#This Row],[cnpj]],empresas_filtradas!A:A,empresas_filtradas!M:M) -> Potencial Planta
A5: 35820448019317 | B5: talvez | C5: CTF_APP e 80km | D5: 13505645 | E5: SP | F5: 6979 | G5: Paulínia/REPLAN/SP | H5: refino_petroquimico | I5: 55.96 | J5: -22.410011 | K5: -47.560393 | L5: Nominatim/OpenStreetMap | M5: Rio Claro | N5: SP | O5: Coordenada aproximada pelo município, não pelo CEP exato. | P5: =_xlfn.XLOOKUP(empresas_identificadas_complementadas[[#This Row],[cnpj]],empresas_filtradas[cnpj],empresas_filtradas[email]) -> ATENDIMENTO@SAC.WHITEMARTINS.COM.BR | Q5: =_xlfn.XLOOKUP(empresas_identificadas_complementadas[[#This Row],[cnpj]],empresas_filtradas!A:A,empresas_filtradas!M:M) -> Potencial Planta
A6: 43843358003023 | B6: talvez | C6: CTF_APP | D6: 18278725 | E6: SP | F6: 7181 | G6: Paulínia/REPLAN/SP | H6: refino_petroquimico | I6: 100.31 | J6: -23.348985 | K6: -47.849016 | L6: Nominatim/OpenStreetMap | M6: Tatuí | N6: SP | O6: Coordenada aproximada pelo município, não pelo CEP exato. | P6: =_xlfn.XLOOKUP(empresas_identificadas_complementadas[[#This Row],[cnpj]],empresas_filtradas[cnpj],empresas_filtradas[email]) -> IMPNFE@AIRPRODUCTS.COM | Q6: =_xlfn.XLOOKUP(empresas_identificadas_complementadas[[#This Row],[cnpj]],empresas_filtradas!A:A,empresas_filtradas!M:M) -> Não Planta
A7: 331788005773 | B7: talvez | C7: CTF_APP | D7: 71225526 | E7: DF | F7: 9701 | G7: Uberaba/MG | H7: fertilizantes_quimico | I7: 439.6 | J7: -15.793987 | K7: -47.8828 | L7: Nominatim/OpenStreetMap | M7: Brasília | N7: DF | O7: Coordenada aproximada pelo município, não pelo CEP exato. | P7: =_xlfn.XLOOKUP(empresas_identificadas_complementadas[[#This Row],[cnpj]],empresas_filtradas[cnpj],empresas_filtradas[email]) -> BRALB-PARALEGAL@AIRLIQUIDE.COM | Q7: =_xlfn.XLOOKUP(empresas_identificadas_complementadas[[#This Row],[cnpj]],empresas_filtradas!A:A,empresas_filtradas!M:M) -> Não Planta
A8: 331788006230 | B8: talvez | C8: CTF_APP | D8: 17034290 | E8: SP | F8: 6219 | G8: Paulínia/REPLAN/SP | H8: refino_petroquimico | I8: 198.27 | J8: -22.30849 | K8: -49.01404 | L8: Nominatim/OpenStreetMap | M8: Bauru | N8: SP | P8: =_xlfn.XLOOKUP(empresas_identificadas_complementadas[[#This Row],[cnpj]],empresas_filtradas[cnpj],empresas_filtradas[email]) -> BRALB-PARALEGAL@AIRLIQUIDE.COM | Q8: =_xlfn.XLOOKUP(empresas_identificadas_complementadas[[#This Row],[cnpj]],empresas_filtradas!A:A,empresas_filtradas!M:M) -> Não Planta
A9: 60619202002272 | B9: talvez | C9: CTF_APP e 80km | D9: 42816140 | E9: BA | F9: 3413 | G9: Camaçari/BA | H9: petroquimico | I9: 3.35 | J9: -12.667485 | K9: -38.314886 | L9: Nominatim/OpenStreetMap | M9: Camaçari | N9: BA | P9: =_xlfn.XLOOKUP(empresas_identificadas_complementadas[[#This Row],[cnpj]],empresas_filtradas[cnpj],empresas_filtradas[email]) -> TAX.COMPLIANCE@MESSER-BR.COM | Q9: =_xlfn.XLOOKUP(empresas_identificadas_complementadas[[#This Row],[cnpj]],empresas_filtradas!A:A,empresas_filtradas!M:M) -> Potencial Planta
A10: 24380578005903 | B10: talvez | C10: CTF_APP | D10: 79602970 | E10: MS | F10: 9165 | G10: Uberaba/MG | H10: fertilizantes_quimico | I10: 408.82 | J10: -20.79173 | K10: -51.696929 | L10: Nominatim/OpenStreetMap | M10: Três Lagoas | N10: MS | P10: =_xlfn.XLOOKUP(empresas_identificadas_complementadas[[#This Row],[cnpj]],empresas_filtradas[cnpj],empresas_filtradas[email]) -> ATENDIMENTO@SAC.WHITEMARTINS.COM.BR | Q10: =_xlfn.XLOOKUP(empresas_identificadas_complementadas[[#This Row],[cnpj]],empresas_filtradas!A:A,empresas_filtradas!M:M) -> Não Planta
A11: 35820448021303 | B11: talvez | C11: CTF_APP e 80km | D11: 13288172 | E11: SP | F11: 7237 | G11: Paulínia/REPLAN/SP | H11: refino_petroquimico | I11: 37.49 | J11: -23.029854 | K11: -46.974985 | L11: Nominatim/OpenStreetMap | M11: Vinhedo | N11: SP | O11: Coordenada aproximada pelo município, não pelo CEP exato. | P11: =_xlfn.XLOOKUP(empresas_identificadas_complementadas[[#This Row],[cnpj]],empresas_filtradas[cnpj],empresas_filtradas[email]) -> ATENDIMENTO@SAC.WHITEMARTINS.COM.BR | Q11: =_xlfn.XLOOKUP(empresas_identificadas_complementadas[[#This Row],[cnpj]],empresas_filtradas!A:A,empresas_filtradas!M:M) -> Potencial Planta
A12: 35820448022024 | B12: talvez | C12: CTF_APP e 80km | D12: 38490000 | E12: MG | F12: 4613 | G12: Uberaba/MG | H12: fertilizantes_quimico | I12: 78.74 | J12: -19.039197 | K12: -47.917844 | L12: Nominatim/OpenStreetMap | M12: Indianópolis | N12: MG | P12: =_xlfn.XLOOKUP(empresas_identificadas_complementadas[[#This Row],[cnpj]],empresas_filtradas[cnpj],empresas_filtradas[email]) -> ATENDIMENTO@SAC.WHITEMARTINS.COM.BR | Q12: =_xlfn.XLOOKUP(empresas_identificadas_complementadas[[#This Row],[cnpj]],empresas_filtradas!A:A,empresas_filtradas!M:M) -> Potencial Planta
A13: 45829243000175 | B13: talvez | D13: 36052590 | E13: MG | F13: 4733 | G13: Duque de Caxias/REDUC/RJ | H13: refino_petroquimico | I13: 106.93 | J13: -21.760953 | K13: -43.350113 | L13: Nominatim/OpenStreetMap | M13: Juiz de Fora | N13: MG | O13: Coordenada aproximada pelo município, não pelo CEP exato. | P13: =_xlfn.XLOOKUP(empresas_identificadas_complementadas[[#This Row],[cnpj]],empresas_filtradas[cnpj],empresas_filtradas[email]) -> CONTABILIDADE@KSCONTABIL.COM.BR | Q13: =_xlfn.XLOOKUP(empresas_identificadas_complementadas[[#This Row],[cnpj]],empresas_filtradas!A:A,empresas_filtradas!M:M) -> Sem Relação
A14: 54443328000101 | B14: talvez | D14: 64200970 | E14: PI | F14: 1153 | G14: Pecém/CE | H14: porto_industrial | I14: 335.57 | J14: -2.9147515 | K14: -41.766195 | L14: Nominatim/OpenStreetMap | M14: Parnaíba | N14: PI | O14: Coordenada aproximada pelo município, não pelo CEP exato. | P14: =_xlfn.XLOOKUP(empresas_identificadas_complementadas[[#This Row],[cnpj]],empresas_filtradas[cnpj],empresas_filtradas[email]) -> INFO@GEP-GLOBAL.COM | Q14: =_xlfn.XLOOKUP(empresas_identificadas_complementadas[[#This Row],[cnpj]],empresas_filtradas!A:A,empresas_filtradas!M:M) -> Conceito de Planta
A15: 331788010939 | B15: talvez | C15: 80km | D15: 42813760 | E15: BA | F15: 3413 | G15: Camaçari/BA | H15: petroquimico | I15: 0.48 | J15: -12.699819 | K15: -38.326076 | L15: Nominatim/OpenStreetMap | M15: Camaçari | N15: BA | O15: Coordenada aproximada pelo município, não pelo CEP exato. | P15: =_xlfn.XLOOKUP(empresas_identificadas_complementadas[[#This Row],[cnpj]],empresas_filtradas[cnpj],empresas_filtradas[email]) -> BRALB-PARALEGAL@AIRLIQUIDE.COM | Q15: =_xlfn.XLOOKUP(empresas_identificadas_complementadas[[#This Row],[cnpj]],empresas_filtradas!A:A,empresas_filtradas!M:M) -> Não Planta
A16: 331788000623 | B16: talvez | C16: CTF_APP e 80km | D16: 26110100 | E16: RJ | F16: 2909 | G16: Duque de Caxias/REDUC/RJ | H16: refino_petroquimico | I16: 10.56 | J16: -22.760191 | K16: -43.365954 | L16: Nominatim/OpenStreetMap | M16: Belford Roxo | N16: RJ | P16: =_xlfn.XLOOKUP(empresas_identificadas_complementadas[[#This Row],[cnpj]],empresas_filtradas[cnpj],empresas_filtradas[email]) -> BRALB-PARALEGAL@AIRLIQUIDE.COM | Q16: =_xlfn.XLOOKUP(empresas_identificadas_complementadas[[#This Row],[cnpj]],empresas_filtradas!A:A,empresas_filtradas!M:M) -> Potencial Planta
A17: 35820448006410 | B17: talvez | C17: CTF_APP e 80km | D17: 95840000 | E17: RS | F17: 8943 | G17: Triunfo/RS | H17: petroquimico | I17: 32.83 | J17: -29.940797 | K17: -51.719186 | L17: Nominatim/OpenStreetMap | M17: Triunfo | N17: RS | P17: =_xlfn.XLOOKUP(empresas_identificadas_complementadas[[#This Row],[cnpj]],empresas_filtradas[cnpj],empresas_filtradas[email]) -> ATENDIMENTO@SAC.WHITEMARTINS.COM.BR | Q17: =_xlfn.XLOOKUP(empresas_identificadas_complementadas[[#This Row],[cnpj]],empresas_filtradas!A:A,empresas_filtradas!M:M) -> Potencial Planta
A18: 35820448010360 | B18: talvez | C18: CTF_APP e 80km | D18: 13212240 | E18: SP | F18: 6619 | G18: Paulínia/REPLAN/SP | H18: refino_petroquimico | I18: 57.43 | J18: -23.188767 | K18: -46.884506 | L18: Nominatim/OpenStreetMap | M18: Jundiaí | N18: SP | O18: Coordenada aproximada pelo município, não pelo CEP exato. | P18: =_xlfn.XLOOKUP(empresas_identificadas_complementadas[[#This Row],[cnpj]],empresas_filtradas[cnpj],empresas_filtradas[email]) -> ATENDIMENTO@SAC.WHITEMARTINS.COM.BR | Q18: =_xlfn.XLOOKUP(empresas_identificadas_complementadas[[#This Row],[cnpj]],empresas_filtradas!A:A,empresas_filtradas!M:M) -> Potencial Planta
A19: 35820448015915 | B19: talvez | C19: CTF_APP e 80km | D19: 13473625 | E19: SP | F19: 6131 | G19: Paulínia/REPLAN/SP | H19: refino_petroquimico | I19: 19.79 | J19: -22.739246 | K19: -47.330603 | L19: Nominatim/OpenStreetMap | M19: Americana | N19: SP | O19: Coordenada aproximada pelo município, não pelo CEP exato. | P19: =_xlfn.XLOOKUP(empresas_identificadas_complementadas[[#This Row],[cnpj]],empresas_filtradas[cnpj],empresas_filtradas[email]) -> ATENDIMENTO@SAC.WHITEMARTINS.COM.BR | Q19: =_xlfn.XLOOKUP(empresas_identificadas_complementadas[[#This Row],[cnpj]],empresas_filtradas!A:A,empresas_filtradas!M:M) -> Potencial Planta
A20: 35820448017454 | B20: talvez | C20: CTF_APP e 80km | D20: 11573900 | E20: SP | F20: 6371 | G20: Cubatão/SP | H20: industrial_siderurgico | I20: 1.64 | J20: -23.884208 | K20: -46.421306 | L20: Nominatim/OpenStreetMap | M20: Cubatão | N20: SP | O20: Coordenada aproximada pelo município, não pelo CEP exato. | P20: =_xlfn.XLOOKUP(empresas_identificadas_complementadas[[#This Row],[cnpj]],empresas_filtradas[cnpj],empresas_filtradas[email]) -> ATENDIMENTO@SAC.WHITEMARTINS.COM.BR | Q20: =_xlfn.XLOOKUP(empresas_identificadas_complementadas[[#This Row],[cnpj]],empresas_filtradas!A:A,empresas_filtradas!M:M) -> Potencial Planta
A21: 2605266000355 | B21: talvez | C21: CTF_APP e 80km | D21: 29092300 | E21: ES | F21: 5705 | G21: Serra/Tubarão/ES | H21: siderurgia_portuario | I21: 2.26 | J21: -20.253925 | K21: -40.243475 | L21: Nominatim/OpenStreetMap | M21: Vitória | N21: ES | P21: =_xlfn.XLOOKUP(empresas_identificadas_complementadas[[#This Row],[cnpj]],empresas_filtradas[cnpj],empresas_filtradas[email]) -> TAX.COMPLIANCE@MESSER-BR.COM | Q21: =_xlfn.XLOOKUP(empresas_identificadas_complementadas[[#This Row],[cnpj]],empresas_filtradas!A:A,empresas_filtradas!M:M) -> Potencial Planta
A22: 24380578000260 | B22: talvez | C22: CTF_APP e 80km | D22: 57055000 | E22: AL | F22: 2785 | G22: Marechal Deodoro/AL | H22: quimico_cloroquimico | I22: 18.91 | J22: -9.6500548 | K22: -35.73356 | L22: Nominatim/OpenStreetMap | M22: Maceió | N22: AL | P22: =_xlfn.XLOOKUP(empresas_identificadas_complementadas[[#This Row],[cnpj]],empresas_filtradas[cnpj],empresas_filtradas[email]) -> ATENDIMENTO@SAC.WHITEMARTINS.COM.BR | Q22: =_xlfn.XLOOKUP(empresas_identificadas_complementadas[[#This Row],[cnpj]],empresas_filtradas!A:A,empresas_filtradas!M:M) -> Potencial Planta
A23: 67423152000178 | B23: talvez | C23: CTF_APP e 80km | D23: 13213009 | E23: SP | F23: 6619 | G23: Paulínia/REPLAN/SP | H23: refino_petroquimico | I23: 53.41 | J23: -23.170018 | K23: -46.933903 | L23: Nominatim/OpenStreetMap | M23: Jundiaí | N23: SP | P23: =_xlfn.XLOOKUP(empresas_identificadas_complementadas[[#This Row],[cnpj]],empresas_filtradas[cnpj],empresas_filtradas[email]) -> IBG@IBG.COM.BR | Q23: =_xlfn.XLOOKUP(empresas_identificadas_complementadas[[#This Row],[cnpj]],empresas_filtradas!A:A,empresas_filtradas!M:M) -> Relação
A24: 24380578004176 | B24: talvez | C24: CTF_APP e 80km | D24: 49170000 | E24: SE | F24: 3171 | G24: Laranjeiras/SE | H24: fertilizantes_amonia | I24: 0.36 | J24: -10.804023 | K24: -37.165834 | L24: Nominatim/OpenStreetMap | M24: Laranjeiras | N24: SE | P24: =_xlfn.XLOOKUP(empresas_identificadas_complementadas[[#This Row],[cnpj]],empresas_filtradas[cnpj],empresas_filtradas[email]) -> ATENDIMENTO@SAC.WHITEMARTINS.COM.BR | Q24: =_xlfn.XLOOKUP(empresas_identificadas_complementadas[[#This Row],[cnpj]],empresas_filtradas!A:A,empresas_filtradas!M:M) -> Potencial Planta
A25: 24380578000936 | B25: talvez | C25: CTF_APP e 80km | D25: 42810000 | E25: BA | F25: 3413 | G25: Camaçari/BA | H25: petroquimico | I25: 0.15 | J25: -12.6975 | K25: -38.32417 | L25: BrasilAPI CEP v2 | M25: Camaçari | N25: BA | P25: =_xlfn.XLOOKUP(empresas_identificadas_complementadas[[#This Row],[cnpj]],empresas_filtradas[cnpj],empresas_filtradas[email]) -> ATENDIMENTO@SAC.WHITEMARTINS.COM.BR | Q25: =_xlfn.XLOOKUP(empresas_identificadas_complementadas[[#This Row],[cnpj]],empresas_filtradas!A:A,empresas_filtradas!M:M) -> Potencial Planta
A26: 34597955002648 | B26: talvez | C26: CTF_APP e 80km | D26: 68448000 | E26: PA | F26: 425 | G26: Barcarena/Vila do Conde/PA | H26: alumina_aluminio_portuario | I26: 3 | J26: -1.5679371 | K26: -48.758283 | L26: Nominatim/OpenStreetMap | M26: Barcarena | N26: PA | P26: =_xlfn.XLOOKUP(empresas_identificadas_complementadas[[#This Row],[cnpj]],empresas_filtradas[cnpj],empresas_filtradas[email]) -> ATENDIMENTO@SAC.WHITEMARTINS.COM.BR | Q26: =_xlfn.XLOOKUP(empresas_identificadas_complementadas[[#This Row],[cnpj]],empresas_filtradas!A:A,empresas_filtradas!M:M) -> Potencial Planta
A27: 35820448003909 | B27: talvez | C27: CTF_APP | D27: 38402324 | E27: MG | F27: 5403 | G27: Uberaba/MG | H27: fertilizantes_quimico | I27: 98.68 | J27: -18.918804 | K27: -48.276784 | L27: Nominatim/OpenStreetMap | M27: Uberlândia | N27: MG | O27: Coordenada aproximada pelo município, não pelo CEP exato. | P27: =_xlfn.XLOOKUP(empresas_identificadas_complementadas[[#This Row],[cnpj]],empresas_filtradas[cnpj],empresas_filtradas[email]) -> ATENDIMENTO@SAC.WHITEMARTINS.COM.BR | Q27: =_xlfn.XLOOKUP(empresas_identificadas_complementadas[[#This Row],[cnpj]],empresas_filtradas!A:A,empresas_filtradas!M:M) -> Não Planta
A28: 60619202001624 | B28: talvez | C28: CTF_APP e 80km | D28: 32210120 | E28: MG | F28: 4371 | G28: Barreiro/BH/MG | H28: industrial_metalurgico | I28: 3.3 | J28: -19.961947 | K28: -44.030128 | L28: Nominatim/OpenStreetMap | M28: Contagem | N28: MG | P28: =_xlfn.XLOOKUP(empresas_identificadas_complementadas[[#This Row],[cnpj]],empresas_filtradas[cnpj],empresas_filtradas[email]) -> TAX.COMPLIANCE@MESSER-BR.COM | Q28: =_xlfn.XLOOKUP(empresas_identificadas_complementadas[[#This Row],[cnpj]],empresas_filtradas!A:A,empresas_filtradas!M:M) -> Potencial Planta
A29: 35820448009940 | B29: talvez | C29: CTF_APP e 80km | D29: 13412201 | E29: SP | F29: 6875 | G29: Paulínia/REPLAN/SP | H29: refino_petroquimico | I29: 52.44 | J29: -22.725165 | K29: -47.649327 | L29: Nominatim/OpenStreetMap | M29: Piracicaba | N29: SP | O29: Coordenada aproximada pelo município, não pelo CEP exato. | P29: =_xlfn.XLOOKUP(empresas_identificadas_complementadas[[#This Row],[cnpj]],empresas_filtradas[cnpj],empresas_filtradas[email]) -> ATENDIMENTO@SAC.WHITEMARTINS.COM.BR | Q29: =_xlfn.XLOOKUP(empresas_identificadas_complementadas[[#This Row],[cnpj]],empresas_filtradas!A:A,empresas_filtradas!M:M) -> Potencial Planta
A30: 35820448019821 | B30: talvez | C30: CTF_APP | D30: 79600001 | E30: MS | F30: 9165 | G30: Uberaba/MG | H30: fertilizantes_quimico | I30: 409.63 | J30: -20.780742 | K30: -51.708283 | L30: Nominatim/OpenStreetMap | M30: Três Lagoas | N30: MS | P30: =_xlfn.XLOOKUP(empresas_identificadas_complementadas[[#This Row],[cnpj]],empresas_filtradas[cnpj],empresas_filtradas[email]) -> ATENDIMENTO@SAC.WHITEMARTINS.COM.BR | Q30: =_xlfn.XLOOKUP(empresas_identificadas_complementadas[[#This Row],[cnpj]],empresas_filtradas!A:A,empresas_filtradas!M:M) -> Não Planta
A31: 331788006150 | B31: talvez | C31: CTF_APP | D31: 15076080 | E31: SP | F31: 7097 | G31: Uberaba/MG | H31: fertilizantes_quimico | I31: 190.42 | J31: -20.825579 | K31: -49.357103 | L31: Nominatim/OpenStreetMap | M31: São José do Rio Preto | N31: SP | P31: =_xlfn.XLOOKUP(empresas_identificadas_complementadas[[#This Row],[cnpj]],empresas_filtradas[cnpj],empresas_filtradas[email]) -> BRALB-PARALEGAL@AIRLIQUIDE.COM | Q31: =_xlfn.XLOOKUP(empresas_identificadas_complementadas[[#This Row],[cnpj]],empresas_filtradas!A:A,empresas_filtradas!M:M) -> Não Planta
A32: 43843358003457 | B32: talvez | C32: CTF_APP | D32: 12523671 | E32: SP | F32: 6469 | G32: Jacareí/SP | H32: gases_industriais | I32: 96.72 | J32: -22.805784 | K32: -45.190893 | L32: Nominatim/OpenStreetMap | M32: Guaratinguetá | N32: SP | O32: Coordenada aproximada pelo município, não pelo CEP exato. | P32: =_xlfn.XLOOKUP(empresas_identificadas_complementadas[[#This Row],[cnpj]],empresas_filtradas[cnpj],empresas_filtradas[email]) -> IMPNFE@AIRPRODUCTS.COM | Q32: =_xlfn.XLOOKUP(empresas_identificadas_complementadas[[#This Row],[cnpj]],empresas_filtradas!A:A,empresas_filtradas!M:M) -> Planta
A33: 24380578006543 | B33: talvez | C33: CTF_APP | D33: 55900000 | E33: PE | F33: 2423 | G33: Suape/PE | H33: porto_industrial | I33: 93.2 | J33: -7.560603 | K33: -34.99591 | L33: Nominatim/OpenStreetMap | M33: Goiana | N33: PE | P33: =_xlfn.XLOOKUP(empresas_identificadas_complementadas[[#This Row],[cnpj]],empresas_filtradas[cnpj],empresas_filtradas[email]) -> ATENDIMENTO@SAC.WHITEMARTINS.COM.BR | Q33: =_xlfn.XLOOKUP(empresas_identificadas_complementadas[[#This Row],[cnpj]],empresas_filtradas!A:A,empresas_filtradas!M:M) -> Não Planta
A34: 35820448020676 | B34: talvez | C34: CTF_APP e 80km | D34: 8613370 | E34: SP | F34: 7151 | G34: ABC/Capuava/SP | H34: petroquimico_industrial | I34: 23.38 | J34: -23.539272 | K34: -46.282107 | L34: Nominatim/OpenStreetMap | M34: Suzano | N34: SP | P34: =_xlfn.XLOOKUP(empresas_identificadas_complementadas[[#This Row],[cnpj]],empresas_filtradas[cnpj],empresas_filtradas[email]) -> ATENDIMENTO@SAC.WHITEMARTINS.COM.BR | Q34: =_xlfn.XLOOKUP(empresas_identificadas_complementadas[[#This Row],[cnpj]],empresas_filtradas!A:A,empresas_filtradas!M:M) -> Potencial Planta
A35: 35820448021052 | B35: talvez | C35: CTF_APP | D35: 79641300 | E35: MS | F35: 9165 | G35: Uberaba/MG | H35: fertilizantes_quimico | I35: 409.34 | J35: -20.78765 | K35: -51.70338 | L35: BrasilAPI CEP v2 | M35: Três Lagoas | N35: MS | P35: =_xlfn.XLOOKUP(empresas_identificadas_complementadas[[#This Row],[cnpj]],empresas_filtradas[cnpj],empresas_filtradas[email]) -> ATENDIMENTO@SAC.WHITEMARTINS.COM.BR | Q35: =_xlfn.XLOOKUP(empresas_identificadas_complementadas[[#This Row],[cnpj]],empresas_filtradas!A:A,empresas_filtradas!M:M) -> Não Planta
A36: 74481011000681 | B36: talvez | C36: CTF_APP e 80km | D36: 81460040 | E36: PR | F36: 7535 | G36: Araucária/REPAR/PR | H36: refino | I36: 22.09 | J36: -25.429596 | K36: -49.271272 | L36: Nominatim/OpenStreetMap | M36: Curitiba | N36: PR | O36: Coordenada aproximada pelo município, não pelo CEP exato. | P36: =_xlfn.XLOOKUP(empresas_identificadas_complementadas[[#This Row],[cnpj]],empresas_filtradas[cnpj],empresas_filtradas[email]) -> LUCAS@IBG.COM.BR | Q36: =_xlfn.XLOOKUP(empresas_identificadas_complementadas[[#This Row],[cnpj]],empresas_filtradas!A:A,empresas_filtradas!M:M) -> Relação
A37: 35820448022458 | B37: talvez | C37: CTF_APP e 80km | D37: 93700000 | E37: RS | F37: 8577 | G37: Canoas/REFAP/RS | H37: refino | I37: 29.07 | J37: -29.674849 | K37: -51.056282 | L37: Nominatim/OpenStreetMap | P37: =_xlfn.XLOOKUP(empresas_identificadas_complementadas[[#This Row],[cnpj]],empresas_filtradas[cnpj],empresas_filtradas[email]) -> ATENDIMENTO@SAC.WHITEMARTINS.COM.BR | Q37: =_xlfn.XLOOKUP(empresas_identificadas_complementadas[[#This Row],[cnpj]],empresas_filtradas!A:A,empresas_filtradas!M:M) -> Potencial Planta
A38: 331788003487 | B38: talvez | C38: CTF_APP | D38: 37905000 | E38: MG | F38: 4525 | G38: Uberaba/MG | H38: fertilizantes_quimico | I38: 177.17 | J38: -20.849166 | K38: -46.712222 | L38: Nominatim/OpenStreetMap | M38: Fortaleza de Minas | N38: MG | P38: =_xlfn.XLOOKUP(empresas_identificadas_complementadas[[#This Row],[cnpj]],empresas_filtradas[cnpj],empresas_filtradas[email]) -> BRALB-PARALEGAL@AIRLIQUIDE.COM | Q38: =_xlfn.XLOOKUP(empresas_identificadas_complementadas[[#This Row],[cnpj]],empresas_filtradas!A:A,empresas_filtradas!M:M) -> Não Planta
A39: 24380578002203 | B39: talvez | C39: CTF_APP e 80km | D39: 54503410 | E39: PE | F39: 2357 | G39: Suape/PE | H39: porto_industrial | I39: 14.96 | J39: -8.2838945 | K39: -35.032098 | L39: Nominatim/OpenStreetMap | M39: Cabo de Santo Agostinho | N39: PE | O39: Coordenada aproximada pelo município, não pelo CEP exato. | P39: =_xlfn.XLOOKUP(empresas_identificadas_complementadas[[#This Row],[cnpj]],empresas_filtradas[cnpj],empresas_filtradas[email]) -> ATENDIMENTO@SAC.WHITEMARTINS.COM.BR | Q39: =_xlfn.XLOOKUP(empresas_identificadas_complementadas[[#This Row],[cnpj]],empresas_filtradas!A:A,empresas_filtradas!M:M) -> Potencial Planta
A40: 34597955000785 | B40: talvez | C40: CTF_APP | D40: 78098280 | E40: MT | F40: 9067 | G40: Uberaba/MG | H40: fertilizantes_quimico | I40: 966.36 | J40: -15.655865 | K40: -55.990373 | L40: Nominatim/OpenStreetMap | M40: Cuiabá | N40: MT | P40: =_xlfn.XLOOKUP(empresas_identificadas_complementadas[[#This Row],[cnpj]],empresas_filtradas[cnpj],empresas_filtradas[email]) -> ATENDIMENTO@SAC.WHITEMARTINS.COM.BR | Q40: =_xlfn.XLOOKUP(empresas_identificadas_complementadas[[#This Row],[cnpj]],empresas_filtradas!A:A,empresas_filtradas!M:M) -> Não Planta
...
